Workbook
Name \0: #REF!
Name \0: #REF!
Name \0: #REF!
Name \0: #REF!
Name \0: #REF!
Name \0: #REF!
Name \0: #REF!
Name \0: #REF!
Name \0: #REF!
Name \0: #REF!
Name \a: #REF!
Name \a: #REF!
Name \a: #REF!
Name \a: #REF!
Name \a: #REF!
Name \a: #REF!
Name \a: #REF!
Name \a: #REF!
Name \a: #REF!
Name \a: #REF!
Name \b: #N/A
Name \C: #REF!
Name \C: #REF!
Name \C: #REF!
Name \C: #REF!
Name \C: #REF!
Name \C: #REF!
Name \C: #REF!
Name \C: #REF!
Name \C: #REF!
Name \C: #REF!
Name \l: #REF!
Name \l: #REF!
Name \l: #REF!
Name \l: #REF!
Name \l: #REF!
Name \l: #REF!
Name \l: #REF!
Name \l: #REF!
Name \l: #REF!
Name \l: #REF!
Name \o: #REF!
Name \o: #REF!
Name \o: #REF!
Name \o: #REF!
Name \o: #REF!
Name \o: #REF!
Name \o: #REF!
Name \o: #REF!
Name \o: #REF!
Name \o: #REF!
Name \p: #REF!
Name \p: #REF!
Name \p: #REF!
Name \p: #REF!
Name \p: #REF!
Name \p: #REF!
Name \p: #REF!
Name \p: #REF!
Name \S: #REF!

Sheet Civil BOQ (LD Patel R1)
A1: Form A-1 Schedule of Quantities & Prices
A2: Sr.No | B2: Description | C2: UOM | D2: Quantity | E2: Rate | F2: Total Amount
A3: 1 | B3: Excavation and Backfilling
B4: Rate includes removal of all kinds of vegetation, small shrubs etc. Dewatering water to be let out of the building area through proper pipes & channels if required. The contractor at his own expenses shall water very well, ram and thoroughly, consolidate the bottom of all excavations & ground before the construction of foundation/footing/plinth beam, filling in basement floor or other work is commenced. The rate for excavation shall include for shoring sides or trenches with approved timber/steel accessories wherever necessary to prevent sides from falling including bailing or pumping out of water if necessary and include If there are any shrubs, bushes, trees, roots of the trees to be removed for min depth 5’0”. Lift & lead outside campus are to be considered to suit the local regulations. Contour level to be taken jointly with the Project Manager and prior written approval be taken before starting any excavation/ filling at every 3 / 5 mt grids for arriving at the actual quantity. Measurements for filling will be taken for consolidated thickness only .Cost to include all and necessary royalty and other permission charges required to execute the works. Unless noted otherwise measurements shall be considered to the edge of PCC only. | F4: =D4*E4 -> 0
B5: General Excavation by mechanical means in all types of soil including dense soil, disintegrated/ weathered / soft rock / Medium Rock including necessary manual excavation for dressing the edges & levelling, all leads and lifts, necessary soil stabilization pre excavation, protection etc in all types of soil except hard rock as specified and directed. The rate shall include the necessary surface preparation required for the Excavation and to its related works as specified and directed. Rate to include carting away of excavated material outside the site. Note: PCC area shall be considered for measurement Rate to include the dressing of excavated surface to be handed over from General excavation contractor to the required level. (Working space & provision of slopes if required for execution shall not be paid separately). | F5: =IF(D5="QRO",0,D5*E5) -> 0
A6: 1.1 | B6: Excavation in soil at all depth | C6: Cum | D6: ='Excavation Qty for BOQ'!I11 -> 20000.884 | E6: 495 | F6: =IF(D6="QRO",0,D6*E6) -> 9900437.6
B7: Same as item No - 1 above but in hard rock/ boulders (Un-poclainable) by chiselling/wedging up to the required level & depth including all leads and lifts, and carting away excavated material outside the site as directed, de-watering of both ground and surface water as specified. Blasting is not allowed. Note:PCC area shall be considered for measurement (Working space & provision of slopes if required for execution shall not be paid separately. Mode of measurement shall be by joint measurements/ levels before and after excavation). | F7: =IF(D7="QRO",0,D7*E7) -> 0
A8: 1.2 | B8: Excavation in Hard rock at all depth | C8: Cum | D8: ='Excavation Qty for BOQ'!I12 -> 2222.3204 | E8: 750 | F8: =IF(D8="QRO",0,D8*E8) -> 1666740.3
A9: 1.3 | B9: Manual Excavation | C9: Cum | D9: QRO | E9: 945 | F9: =IF(D9="QRO",0,D9*E9) -> 0
B10: Backfilling with approved good quality earth in plinths, below grade slab, behind retaining wall etc. in layers not exceeding depths mentioned below, breaking clods, watering, compacting each layer with vibratory compactor (Vibratory Roller/Compactor capacity i.e. 8 to 10 Tonne) and at inaccessible places with 2 Ton Roller/Plate Compactor to achieve required proctor density mentioned below with optimum moisture content as mentioned below; dressing up embankments; if required, bailing/pumping out of water to keep site dry while backfilling; rate to includes conveyance of all materials, labour, machinery etc. complete as per direction of the EIC to his entire satisfaction. The rate is inclusive of Dewatering. Notes: (1) Field compaction: 98% for Plinth area and 95% for other areas (2) Layers thickness of filling: 150mm compacted in Plinth area filling and 200mm compacted in other filling areas (3) Field density tests: 1 test / 5 Sq.m. for each layer in plinth filling area and 1 test / 50 Sq.m. in other filling area by Sand replacement method as per IS 2720 Part 28 (Latest revision) (4) The measurement shall be for the net compacted volume of filling done. Block levels at intervals of 5 X 5 m or as directed by the Engineer shall be jointly recorded for the measurement purpose, before the start of filling. The acceptance criteria for backfilling works like formation levels, method of compaction, optimum moisture content variation etc. Complete. Please refer Tender Document, Preamble to BOQ, Standard Conditions of Contract, All annexures attached in Tender Document etc. as these all shall be considered in Rates Quoted in BOQ. Mode of Measurement - Actual Filling Area in Cum | F10: =IF(D10="QRO",0,D10*E10) -> 0
A11: 1.5 | B11: With selected excavated material available within plot. | C11: Cum | D11: ='Excavation Qty for BOQ'!I17 -> 9621.071 | E11: 425 | F11: =IF(D11="QRO",0,D11*E11) -> 4088955.2
A12: 1.6 | B12: With approved quality of earth brought from outside | C12: Cum | D12: QRO | E12: 460 | F12: =IF(D12="QRO",0,D12*E12) -> 0
B13: Providing and applying anti termite treatment using approved chemical, conforming to IS 6313 part II (Latest Revision) and approved Method Statement using chemical at 5ltr/sqm of application area or as per manufacture recommendation that shall create a chemical barrier under and around the foundation pits, along external perimeter of building, surroundings of pipes, conduits, etc.; all complete and conforming to specifications and/ or as per approved manufacturer's instructions/recommendation, initial level supervision and application by manufacturer's approved agency with a guarantee of 10 years by Manufacturer and Contractor, all to the satisfaction of the EIC. (Plinth area in plan at ground level shall be measured as per IS 3861). Commencement of work shall be done as per approved method statement. Area at plinth level will be considered for payment.. (Rates include material+labour,tranportation+wastage etc) | F13: =IF(D13="QRO",0,D13*E13) -> 0
A14: 1.7 | B14: Anti Termite | C14: Sqm | D14: =Excavation!I14 -> 2077.24 | E14: 130 | F14: =IF(D14="QRO",0,D14*E14) -> 270041.2
A15: 1.8 | B15: Providing and applying two component coal-tar based epoxy protective coating of approved manufacture to be applied externally on concrete surfaces directly in contact with soil, following manufactures specification as directed by EIC Mode of Measurment:Actual Area of Application | C15: Sqm | D15: QRO | F15: =IF(D15="QRO",0,D15*E15) -> 0
B16: Providing and laying in position minimum 230mm thick Soling, base preparation by Mechanical compaction, using deccan trap basalt hand broken / Rubble for void filling, murrum for binding including watering,packing,compaction etc. in under floor, foundation, pavement, roads, steps, ramps, soak pit and other similar locations, hand set vertically in regular lines, interstices filled in with smaller stone chips including watering and Compaction / consolidating & finishing to the required levels and lines etc with mechanical rammer / manual compaction etc. complete as directed by EIC and as mentioned in Specification and drawing, etc Complete. (Binding layer shall be of metal, sand or murrum which shall be part of Rate quoted). Please refer Tender Document, Preamble to BOQ, Standard Conditions of Contract, All annexures attached in Tender Document etc. as these all shall be considered in Rates Quoted in BOQ.(Rates include material+labour,tranportation+wastage etc) | F16: =IF(D16="QRO",0,D16*E16) -> 0
A17: 1.9 | B17: Soling | C17: Cum | D17: QRO | E17: 500.4 | F17: =IF(D17="QRO",0,D17*E17) -> 0
B18: Excavation Total | F18: =SUM(F4:F17) -> 15926174
F19: =IF(D19="QRO",0,D19*E19) -> 0
A20: 2 | B20: RCC
A21: 2.1 | B21: READY MIX CONCRETE / CONTROLLED CONCRETE | F21: =IF(D21="QRO",0,D21*E21) -> 0
B22: Providing, batching, mixing, transporting through transit mixers, pumping and laying Reinforced Cement Concrete of specified grade at all levels and heights, elevations, projections, surfaces specified below using ordinary Portland cement of grade 53 from approved manufacturer, river sand/manufactured sand, 20mm and down size coarse aggregates, necessary admixtures approved by Consultants/as specified in the contract document, including all leads and lifts, pumping using line pump or boom placer, vibrating/ compaction, scaffolding wherever necessary, curing, treatment of construction joints, necessary co-ordination for Post tensioning works if any etc. complete as directed by the EIC, excluding cost of shuttering and centering. The cost shall include any additional enhancers required to make the concrete more durable or to achieve the strength as per instruction of structural consultant. All necessary treatment to honey combed areas, uneven concrete surfaces shall be made proper as per the structural consultant without any extra cost | F22: =IF(D22="QRO",0,D22*E22) -> 0
B23: (Design mix shall be as approved by the Structural Consultant / Employers representative.) | F23: =IF(D23="QRO",0,D23*E23) -> 0
B24: Note: RMC to be outsourced | F24: =IF(D24="QRO",0,D24*E24) -> 0
B25: Providing and laying specified Grade concrete for P.C.C. of specified thick wherever specified using Manufactured sand, 20mm and downsize metal including base preparation, Compaction, levelling, all leads and lifts, curing and shuttering if necessary etc., Complete | F25: =IF(D25="QRO",0,D25*E25) -> 0
A26: 2.1.1 | B26: M15-PCC | C26: Cum | D26: ='Concrete & Steel Summary'!D84 -> 683.614 | E26: 7146.1 | F26: =IF(D26="QRO",0,D26*E26) -> 4885174
A27: 2.1.2 | B27: M20-PCC | C27: Cum | D27: QRO | E27: 7515.25 | F27: =IF(D27="QRO",0,D27*E27) -> 0
A28: 2.1.3 | B28: M10- Lean Mix | C28: Cum | D28: QRO | E28: 6776.95 | F28: =IF(D28="QRO",0,D28*E28) -> 0
B29: Providing and laying 0f M20 grade concrete for Plum concrete wherever specified using manufactured sand, 40mm and down size metal and boulders of 150mm (proportion 60: 40 for boulder : Concrete ) of approved design mix including sub grade preparation, levelling, surface preparation, all leads and lifts, rough finishing at the top surface, curing and shuttering if necessary etc. | F29: =IF(D29="QRO",0,D29*E29) -> 0
A30: 2.1.4 | B30: Plum Concrete | C30: Cum | D30: ='Excavation Qty for BOQ'!I20 -> 108.0832 | E30: 5520.69 | F30: =IF(D30="QRO",0,D30*E30) -> 596693.84
B31: Providing and Laying approved design mix of concrete for Reinforced Cement Concrete (RCC) work confirming to IS 456 and as specified in drawing and technical specifications. Rate shall include the following :- Handling and transportation, labour, plant & tools, mechanical mixing, placing to required location by hoisting and / or pumping, lubrication of concrete pump line and mechnical vibration, compaction, finishing, curing by any means like by portable water and / or curing compound etc. scaffolding, dewatering, if any hacking of concrete surface wherever required etc. post concrete laitance and slurry removal, making concrete form finish complete at all floors, height and levels as directed by EIC. Forming projections, sinking of floors for sumps wherever directed, forming opening or niches, opening for services and providing dowel bars and also co-ordinating with other agencies for laying conduits, boxes, pipes, clamps etc. as directed at site and making sure they do not get damaged or chocked during concreting. Forming construction joints / expansion strips as directed by the EIC including keys, slopes, falls, temporary stops etc. complete. Any approved make admixture confirming to IS 9103, the contractor may use in order to enhance the workability / properties, any cost towards making concrete water-tight and crack free shall be the part of the item and no extra claim shall be entertained to achieve the same. This rate shall exclude the cost of formwork, shuttering and steel reinforcement. The cost of the testing has to borne by the concractor and no extra claim will be entertained on this account. Location :- Raft/ Foundation
A32: 2.1.5 | B32: M50 from outsourced RMC plant. | C32: Cum | D32: ='Concrete & Steel Summary'!D66 -> 6165.605 | E32: 10238.45 | F32: =IF(D32="QRO",0,D32*E32) -> 63126239
B34: Providing and Laying approved design mix of concrete for Reinforced Cement Concrete (RCC) work confirming to IS 456 and as specified in drawing and technical specifications. Rate shall include the following :- Handling and transportation, labour, plant & tools, mechanical mixing, placing to required location by hoisting and / or pumping, lubrication of concrete pump line and mechnical vibration, compaction, finishing, curing by any means like by portable water and / or curing compound etc. scaffolding, dewatering, if any hacking of concrete surface wherever required etc. post concrete laitance and slurry removal, making concrete form finish complete at all floors, height and levels as directed by EIC. Forming projections, sinking of floors for sumps wherever directed, forming opening or niches, opening for services and providing dowel bars and also co-ordinating with other agencies for laying conduits, boxes, pipes, clamps etc. as directed at site and making sure they do not get damaged or chocked during concreting. Forming construction joints / expansion strips as directed by the EIC including keys, slopes, falls, temporary stops etc. complete. Any approved make admixture confirming to IS 9103, the contractor may use in order to enhance the workability / properties, any cost towards making concrete water-tight and crack free shall be the part of the item and no extra claim shall be entertained to achieve the same. This rate shall exclude the cost of formwork, shuttering and steel reinforcement. The cost of the testing has to borne by the concractor and no extra claim will be entertained on this account. Columns may be free standing or integrated with shear / lift walls, they may be floating on or hanging from beams, rectangular, T shaped, L shaped or square columns, pedestral or stup columns, composite columns, butteress for retaining wall of different sizes and shapes at various levels / heights.
A35: 2.1.5 | B35: Column | F35: =IF(D35="QRO",0,D35*E35) -> 0
B36: M60 | C36: Cum | D36: QRO | E36: 10584.6 | F36: =IF(D36="QRO",0,D36*E36) -> 0
B37: M50 | C37: Cum | D37: ='Concrete & Steel Summary'!D70 -> 9560.372 | E37: =E32 -> 10238.45 | F37: =IF(D37="QRO",0,D37*E37) -> 97883391
B38: M40 | C38: Cum | D38: QRO | E38: 9600.2 | F38: =IF(D38="QRO",0,D38*E38) -> 0
A39: 2.1.6 | B39: Retaining Wall
B40: M50 | C40: Cum | D40: ='Concrete & Steel Summary'!D67 -> 336.4548 | E40: =E37 -> 10238.45 | F40: =IF(D40="QRO",0,D40*E40) -> 3444775.6
A41: 2.1.7 | B41: UGT, OHT, LMR, Swimming Pool and Parapet Wall
...

Sheet Civil BOQ (Punit Rates R2)
A1: Form A-1 Schedule of Quantities & Prices
A2: Sr.No | B2: Description | C2: UOM | D2: Quantity | E2: Rate | F2: Total Amount
A3: 1 | B3: Excavation and Backfilling
B4: Rate includes removal of all kinds of vegetation, small shrubs etc. Dewatering water to be let out of the building area through proper pipes & channels if required. The contractor at his own expenses shall water very well, ram and thoroughly, consolidate the bottom of all excavations & ground before the construction of foundation/footing/plinth beam, filling in basement floor or other work is commenced. The rate for excavation shall include for shoring sides or trenches with approved timber/steel accessories wherever necessary to prevent sides from falling including bailing or pumping out of water if necessary and include If there are any shrubs, bushes, trees, roots of the trees to be removed for min depth 5’0”. Lift & lead outside campus are to be considered to suit the local regulations. Contour level to be taken jointly with the Project Manager and prior written approval be taken before starting any excavation/ filling at every 3 / 5 mt grids for arriving at the actual quantity. Measurements for filling will be taken for consolidated thickness only .Cost to include all and necessary royalty and other permission charges required to execute the works. Unless noted otherwise measurements shall be considered to the edge of PCC only. | F4: =D4*E4 -> 0
B5: General Excavation by mechanical means in all types of soil including dense soil, disintegrated/ weathered / soft rock / Medium Rock including necessary manual excavation for dressing the edges & levelling, all leads and lifts, necessary soil stabilization pre excavation, protection etc in all types of soil except hard rock as specified and directed. The rate shall include the necessary surface preparation required for the Excavation and to its related works as specified and directed. Rate to include carting away of excavated material outside the site. Note: PCC area shall be considered for measurement Rate to include the dressing of excavated surface to be handed over from General excavation contractor to the required level. (Working space & provision of slopes if required for execution shall not be paid separately). | F5: =IF(D5="QRO",0,D5*E5) -> 0
A6: 1.1 | B6: Excavation in soil at all depth with in the plot | C6: Cum | D6: =D12 -> 9621.071 | E6: 250 | F6: =IF(D6="QRO",0,D6*E6) -> 2405267.8
B7: Excavation in soil at all depth outside the plot | C7: Cum | D7: ='Excavation Qty for BOQ'!I11-D6 -> 10379.813 | E7: 752.27 | F7: =IF(D7="QRO",0,D7*E7) -> 7808422
B8: Same as item No - 1 above but in hard rock/ boulders (Un-poclainable) by chiselling/wedging up to the required level & depth including all leads and lifts, and carting away excavated material outside the site as directed, de-watering of both ground and surface water as specified. Blasting is not allowed. Note:PCC area shall be considered for measurement (Working space & provision of slopes if required for execution shall not be paid separately. Mode of measurement shall be by joint measurements/ levels before and after excavation). | F8: =IF(D8="QRO",0,D8*E8) -> 0
A9: 1.2 | B9: Excavation in Hard rock at all depth | C9: Cum | D9: ='Excavation Qty for BOQ'!I12 -> 2222.3204 | E9: 1069.22 | F9: =IF(D9="QRO",0,D9*E9) -> 2376149.5
A10: 1.3 | B10: Manual Excavation | C10: Cum | D10: QRO | E10: 2770 | F10: =IF(D10="QRO",0,D10*E10) -> 0
B11: Backfilling with approved good quality earth in plinths, below grade slab, behind retaining wall etc. in layers not exceeding depths mentioned below, breaking clods, watering, compacting each layer with vibratory compactor (Vibratory Roller/Compactor capacity i.e. 8 to 10 Tonne) and at inaccessible places with 2 Ton Roller/Plate Compactor to achieve required proctor density mentioned below with optimum moisture content as mentioned below; dressing up embankments; if required, bailing/pumping out of water to keep site dry while backfilling; rate to includes conveyance of all materials, labour, machinery etc. complete as per direction of the EIC to his entire satisfaction. The rate is inclusive of Dewatering. Notes: (1) Field compaction: 98% for Plinth area and 95% for other areas (2) Layers thickness of filling: 150mm compacted in Plinth area filling and 200mm compacted in other filling areas (3) Field density tests: 1 test / 5 Sq.m. for each layer in plinth filling area and 1 test / 50 Sq.m. in other filling area by Sand replacement method as per IS 2720 Part 28 (Latest revision) (4) The measurement shall be for the net compacted volume of filling done. Block levels at intervals of 5 X 5 m or as directed by the Engineer shall be jointly recorded for the measurement purpose, before the start of filling. The acceptance criteria for backfilling works like formation levels, method of compaction, optimum moisture content variation etc. Complete. Please refer Tender Document, Preamble to BOQ, Standard Conditions of Contract, All annexures attached in Tender Document etc. as these all shall be considered in Rates Quoted in BOQ. Mode of Measurement - Actual Filling Area in Cum | F11: =IF(D11="QRO",0,D11*E11) -> 0
A12: 1.5 | B12: With selected excavated material available within plot. | C12: Cum | D12: ='Excavation Qty for BOQ'!I17 -> 9621.071 | E12: 166.2 | F12: =IF(D12="QRO",0,D12*E12) -> 1599022
A13: 1.6 | B13: With approved quality of earth brought from outside | C13: Cum | D13: QRO | E13: 770.06 | F13: =IF(D13="QRO",0,D13*E13) -> 0
B14: Providing and applying anti termite treatment using approved chemical, conforming to IS 6313 part II (Latest Revision) and approved Method Statement using chemical at 5ltr/sqm of application area or as per manufacture recommendation that shall create a chemical barrier under and around the foundation pits, along external perimeter of building, surroundings of pipes, conduits, etc.; all complete and conforming to specifications and/ or as per approved manufacturer's instructions/recommendation, initial level supervision and application by manufacturer's approved agency with a guarantee of 10 years by Manufacturer and Contractor, all to the satisfaction of the EIC. (Plinth area in plan at ground level shall be measured as per IS 3861). Commencement of work shall be done as per approved method statement. Area at plinth level will be considered for payment.. (Rates include material+labour,tranportation+wastage etc) | F14: =IF(D14="QRO",0,D14*E14) -> 0
A15: 1.7 | B15: Anti Termite | C15: Sqm | D15: =Excavation!I14 -> 2077.24 | E15: 96.95 | F15: =IF(D15="QRO",0,D15*E15) -> 201388.42
A16: 1.8 | B16: Providing and applying two component coal-tar based epoxy protective coating of approved manufacture to be applied externally on concrete surfaces directly in contact with soil, following manufactures specification as directed by EIC Mode of Measurment:Actual Area of Application | C16: Sqm | D16: QRO | F16: =IF(D16="QRO",0,D16*E16) -> 0
B17: Providing and laying in position minimum 230mm thick Soling, base preparation by Mechanical compaction, using deccan trap basalt hand broken / Rubble for void filling, murrum for binding including watering,packing,compaction etc. in under floor, foundation, pavement, roads, steps, ramps, soak pit and other similar locations, hand set vertically in regular lines, interstices filled in with smaller stone chips including watering and Compaction / consolidating & finishing to the required levels and lines etc with mechanical rammer / manual compaction etc. complete as directed by EIC and as mentioned in Specification and drawing, etc Complete. (Binding layer shall be of metal, sand or murrum which shall be part of Rate quoted). Please refer Tender Document, Preamble to BOQ, Standard Conditions of Contract, All annexures attached in Tender Document etc. as these all shall be considered in Rates Quoted in BOQ.(Rates include material+labour,tranportation+wastage etc) | F17: =IF(D17="QRO",0,D17*E17) -> 0
A18: 1.9 | B18: Soling | C18: Cum | D18: =(D53/0.2)*0.23 -> 726.08636 | E18: 2491.62 | F18: =IF(D18="QRO",0,D18*E18) -> 1809131.3
B19: Excavation Total | F19: =SUM(F4:F18) -> 16199381
F20: =IF(D20="QRO",0,D20*E20) -> 0
A21: 2 | B21: RCC
A22: 2.1 | B22: READY MIX CONCRETE / CONTROLLED CONCRETE | F22: =IF(D22="QRO",0,D22*E22) -> 0
B23: Providing, batching, mixing, transporting through transit mixers, pumping and laying Reinforced Cement Concrete of specified grade at all levels and heights, elevations, projections, surfaces specified below using ordinary Portland cement of grade 53 from approved manufacturer, river sand/manufactured sand, 20mm and down size coarse aggregates, necessary admixtures approved by Consultants/as specified in the contract document, including all leads and lifts, pumping using line pump or boom placer, vibrating/ compaction, scaffolding wherever necessary, curing, treatment of construction joints, necessary co-ordination for Post tensioning works if any etc. complete as directed by the EIC, excluding cost of shuttering and centering. The cost shall include any additional enhancers required to make the concrete more durable or to achieve the strength as per instruction of structural consultant. All necessary treatment to honey combed areas, uneven concrete surfaces shall be made proper as per the structural consultant without any extra cost | F23: =IF(D23="QRO",0,D23*E23) -> 0
B24: (Design mix shall be as approved by the Structural Consultant / Employers representative.) | F24: =IF(D24="QRO",0,D24*E24) -> 0
B25: Providing and laying specified Grade concrete for P.C.C. of specified thick wherever specified using Manufactured sand, 20mm and downsize metal including base preparation, Compaction, levelling, all leads and lifts, curing and shuttering if necessary etc., Complete | F25: =IF(D25="QRO",0,D25*E25) -> 0
A26: 2.1.1 | B26: M15-PCC Outsourced RMC plant. | C26: Cum | D26: ='Concrete & Steel Summary'!D84 -> 683.614 | E26: 8939.31 | F26: =IF(D26="QRO",0,D26*E26) -> 6111037.5
A27: 2.1.2 | B27: M20-PCC Outsourced RMC plant. | C27: Cum | D27: QRO | E27: 10175.44 | F27: =IF(D27="QRO",0,D27*E27) -> 0
A28: 2.1.3 | B28: M10- Lean Mix Outsourced RMC plant. | C28: Cum | D28: QRO | E28: 8033 | F28: =IF(D28="QRO",0,D28*E28) -> 0
B29: Providing and laying 0f M20 grade concrete for Plum concrete wherever specified using manufactured sand, 40mm and down size metal and boulders of 150mm (proportion 60: 40 for boulder : Concrete ) of approved design mix including sub grade preparation, levelling, surface preparation, all leads and lifts, rough finishing at the top surface, curing and shuttering if necessary etc. | F29: =IF(D29="QRO",0,D29*E29) -> 0
A30: 2.1.4 | B30: Plum Concrete Outsourced RMC plant. | C30: Cum | D30: ='Excavation Qty for BOQ'!I20 -> 108.0832 | E30: 7509.02 | F30: =IF(D30="QRO",0,D30*E30) -> 811598.91
B31: Providing and Laying approved design mix of concrete for Reinforced Cement Concrete (RCC) work confirming to IS 456 and as specified in drawing and technical specifications. Rate shall include the following :- Handling and transportation, labour, plant & tools, mechanical mixing, placing to required location by hoisting and / or pumping, lubrication of concrete pump line and mechnical vibration, compaction, finishing, curing by any means like by portable water and / or curing compound etc. scaffolding, dewatering, if any hacking of concrete surface wherever required etc. post concrete laitance and slurry removal, making concrete form finish complete at all floors, height and levels as directed by EIC. Forming projections, sinking of floors for sumps wherever directed, forming opening or niches, opening for services and providing dowel bars and also co-ordinating with other agencies for laying conduits, boxes, pipes, clamps etc. as directed at site and making sure they do not get damaged or chocked during concreting. Forming construction joints / expansion strips as directed by the EIC including keys, slopes, falls, temporary stops etc. complete. Any approved make admixture confirming to IS 9103, the contractor may use in order to enhance the workability / properties, any cost towards making concrete water-tight and crack free shall be the part of the item and no extra claim shall be entertained to achieve the same. This rate shall exclude the cost of formwork, shuttering and steel reinforcement. The cost of the testing has to borne by the concractor and no extra claim will be entertained on this account. Location :- Raft/ Foundation
A32: 2.1.5 | B32: M50 from Inhouse RMC plant. | C32: Cum | D32: ='Concrete & Steel Summary'!D66 -> 6165.605 | E32: =11531.51-300 -> 11231.51 | F32: =IF(D32="QRO",0,D32*E32) -> 69249054
A33: 2.1.6 | B33: M50 from Outsourced RMC plant. | C33: Cum | D33: QRO | E33: 11531.51 | G33: Basic Cement Rate
B34: Providing and Laying approved design mix of concrete for Reinforced Cement Concrete (RCC) work confirming to IS 456 and as specified in drawing and technical specifications. Rate shall include the following :- Handling and transportation, labour, plant & tools, mechanical mixing, placing to required location by hoisting and / or pumping, lubrication of concrete pump line and mechnical vibration, compaction, finishing, curing by any means like by portable water and / or curing compound etc. scaffolding, dewatering, if any hacking of concrete surface wherever required etc. post concrete laitance and slurry removal, making concrete form finish complete at all floors, height and levels as directed by EIC. Forming projections, sinking of floors for sumps wherever directed, forming opening or niches, opening for services and providing dowel bars and also co-ordinating with other agencies for laying conduits, boxes, pipes, clamps etc. as directed at site and making sure they do not get damaged or chocked during concreting. Forming construction joints / expansion strips as directed by the EIC including keys, slopes, falls, temporary stops etc. complete. Any approved make admixture confirming to IS 9103, the contractor may use in order to enhance the workability / properties, any cost towards making concrete water-tight and crack free shall be the part of the item and no extra claim shall be entertained to achieve the same. This rate shall exclude the cost of formwork, shuttering and steel reinforcement. The cost of the testing has to borne by the concractor and no extra claim will be entertained on this account. Columns may be free standing or integrated with shear / lift walls, they may be floating on or hanging from beams, rectangular, T shaped, L shaped or square columns, pedestral or stup columns, composite columns, butteress for retaining wall of different sizes and shapes at various levels / heights.
A35: 2.1.5 | B35: Column | F35: =IF(D35="QRO",0,D35*E35) -> 0
B36: M60 Inhouse RMC plant. | C36: Cum | D36: QRO | F36: =IF(D36="QRO",0,D36*E36) -> 0
B37: M60 Outsourced RMC plant. | C37: Cum | D37: QRO | F37: =IF(D37="QRO",0,D37*E37) -> 0
B38: M50 Inhouse RMC plant. | C38: Cum | D38: ='Concrete & Steel Summary'!D70 -> 9560.372 | E38: =11531.51-300 -> 11231.51 | F38: =IF(D38="QRO",0,D38*E38) -> 1.0737741e+08
B39: M50 Outsourced RMC plant. | C39: Cum | D39: QRO | E39: =11531.51 -> 11531.51
B40: M40 Inhouse RMC plant. | C40: Cum | D40: QRO | E40: =E41-300 -> 10404.48 | F40: =IF(D40="QRO",0,D40*E40) -> 0
...

Sheet Excavation Qty for BOQ
A1: Excavation, Backfilling & ATT
A2: Sr. No. | B2: Work/ Item Description | C2: Concrete Grade | D2: Nos | E2: Length M | F2: Width M | G2: Depth M | H2: Area Sq M | I2: Volume Cu M | J2: Rate | K2: Amount
A3: A | B3: Excavation
B4: Excavation in Soil - Plinth Area (Bldg Area) | D4: 1 | G4: 7.5 | H4: 2077.24 | I4: =PRODUCT(D4:H4) -> 15579.3 | K4: =I4*J4 -> 0
B5: Excavation in Soil - Plinth Area (Podium Area) | D5: 1 | G5: =5.9-1.8 -> 4.1 | H5: 1340.75 | I5: =PRODUCT(D5:H5) -> 5497.075 | K5: =I5*J5 -> 0
B6: Excavation - UG Tank Soil | D6: 1 | G6: 0.9 | H6: 281.75 | I6: =PRODUCT(D6:H6) -> 253.575 | K6: =I6*J6 -> 0
B7: Excavation - Lift Pit Soil | D7: 1 | G7: 2 | H7: =40.08*2 -> 80.16 | I7: =PRODUCT(D7:H7) -> 160.32 | K7: =I7*J7 -> 0
B8: Storm water drain in Soil | E8: 257.17 | F8: 1.5 | G8: 1.5 | I8: =PRODUCT(D8:H8) -> 578.6325 | K8: =I8*J8 -> 0
B9: Fire line/Electrical line in Soil | E9: 257.17 | F9: 0.6 | G9: 1 | I9: =PRODUCT(D9:H9) -> 154.302 | K9: =I9*J9 -> 0
B10: Total for Excavation | I10: =SUM(I4:I9) -> 22223.204 | K10: =SUM(K4:K9) -> 0 | M10: =I10*0.4 -> 8889.2818
B11: Total Excavation in Soil | I11: =I10*0.9 -> 20000.884
B12: Total Excavation in Rock | I12: =I10-I11 -> 2222.3204
A14: B | B14: Backfilling
B15: Murum Filling in Bldg Area above Raft | D15: 1 | G15: 2.9 | H15: =H4 -> 2077.24 | I15: =PRODUCT(D15:H15) -> 6023.996
B16: Filling in Drive way/LOS Area | D16: 1 | G16: =37.8-36.3 -> 1.5 | H16: 2398.05 | I16: =PRODUCT(D16:H16) -> 3597.075
B17: Total Backfilling with Soil within the plot | I17: =SUM(I15:I16) -> 9621.071
A19: C | B19: Plum Concrete for Edges at Level Difference
B20: Plum Concrete | E20: 84.44 | H20: =0.5*1.6*1.6 -> 1.28 | I20: =PRODUCT(D20:H20) -> 108.0832

Sheet Construction Area
A1: Project - Mulund
A2: Area Statement -Construction Area
A3: Mulund
A4: Sr.No. | B4: Description | C4: Floorplate Area (P line) | D4: Deduction | G4: Addition | P4: Total | Q4: No | R4: Total Construction Area (in Sq.m) | S4: Total Construction Area (in sq.ft)
D5: Lift Shaft | E5: MEP Shaft | F5: Void | G5: S Slab | H5: Deck /Balcony | I5: Utility/Dry Balcony | J5: Chajja | K5: Tower Area | L5: NTA Open to sky | M5: Terrace | N5: Beam for Jalli | O5: Refuge | V5: As per EC
A6: 1 | B6: Basement | C6: 3286.5 | D6: -71.26 | E6: -4.04 | F6: 0 | G6: 0 | H6: 0 | I6: 0 | J6: 0 | K6: 0 | L6: 0 | M6: 0 | N6: 0 | O6: 0 | P6: =SUM(C6:O6) -> 3211.2 | Q6: 1 | R6: =Q6*P6 -> 3211.2 | S6: =R6*10.764 -> 34565.357 | V6: =+S6 -> 34565.357
A7: 2 | B7: Ground Floor | C7: 3365.01 | D7: -71.26 | E7: -3.28 | F7: -128.74 | G7: 0 | H7: 0 | I7: 0 | J7: 0 | K7: 0 | L7: 0 | M7: 0 | N7: 0 | O7: 0 | P7: =SUM(C7:O7) -> 3161.73 | Q7: 1 | R7: =Q7*P7 -> 3161.73 | S7: =R7*10.764 -> 34032.862 | V7: =+S7 -> 34032.862
A8: 3 | B8: 1st Podium | C8: 2884.96 | D8: -71.26 | E8: -8.44 | F8: -111.23 | G8: 0 | H8: 0 | I8: 0 | J8: 7.02 | K8: 0 | L8: 0 | M8: 0 | N8: 0 | O8: 0 | P8: =SUM(C8:O8) -> 2701.05 | Q8: 1 | R8: =Q8*P8 -> 2701.05 | S8: =R8*10.764 -> 29074.102 | U8: =R7-R15 -> 1918.53 | V8: =+S8 -> 29074.102
A9: 4 | B9: 2nd Podium | C9: 2884.96 | D9: -71.26 | E9: -8.44 | F9: -142.7 | G9: 0 | H9: 0 | I9: 0 | J9: 7.02 | K9: 0 | L9: 0 | M9: 0 | N9: 0 | O9: 0 | P9: =SUM(C9:O9) -> 2669.58 | Q9: 1 | R9: =Q9*P9 -> 2669.58 | S9: =R9*10.764 -> 28735.359 | V9: =+S9 -> 28735.359
A10: 5 | B10: 3rd Podium | C10: =C9 -> 2884.96 | D10: =D9 -> -71.26 | E10: =E9 -> -8.44 | F10: -142.7 | G10: =G9 -> 0 | H10: =H9 -> 0 | I10: =I9 -> 0 | J10: =J9 -> 7.02 | K10: =K9 -> 0 | L10: =L9 -> 0 | M10: =M9 -> 0 | N10: =N9 -> 0 | O10: =O9 -> 0 | P10: =SUM(C10:O10) -> 2669.58 | Q10: 1 | R10: =Q10*P10 -> 2669.58 | S10: =R10*10.764 -> 28735.359 | V10: =+S10 -> 28735.359
A11: 6 | B11: 4th Podium | C11: 2717.55 | D11: -56.77 | E11: =E9 -> -8.44 | F11: -143.41 | G11: =G10 -> 0 | H11: =H10 -> 0 | I11: =I10 -> 0 | J11: 7.09 | K11: =K10 -> 0 | L11: =L10 -> 0 | M11: 167.4 | N11: =N10 -> 0 | O11: =O10 -> 0 | P11: =SUM(C11:O11) -> 2683.42 | Q11: 1 | R11: =Q11*P11 -> 2683.42 | S11: =R11*10.764 -> 28884.333 | V11: =+S11 -> 28884.333
A12: 7 | B12: 5th Podium | C12: 2749.87 | D12: -56.77 | E12: -13.72 | F12: -378.2 | G12: =G11 -> 0 | H12: 13.4 | I12: 12.94 | J12: 46.67 | K12: 0 | L12: 0 | M12: 0 | O12: =O11 -> 0 | P12: =SUM(C12:O12) -> 2374.19 | Q12: 1 | R12: =Q12*P12 -> 2374.19 | S12: =R12*10.764 -> 25555.781 | V12: =+S12 -> 25555.781
A13: 8 | B13: 6th Podium | C13: 2745.96 | D13: -56.77 | E13: -19.57 | F13: -202.91 | G13: 1.09 | H13: 13.4 | I13: 12.94 | J13: 46.67 | K13: =1371.78*0 -> 0 | L13: =(C13-K13)*0 -> 0 | M13: 0 | N13: 0.42 | O13: =O12 -> 0 | P13: =SUM(C13:O13) -> 2541.23 | Q13: 1 | R13: =Q13*P13 -> 2541.23 | S13: =R13*10.764 -> 27353.8 | V13: =+S14 -> 13576.418
A14: 9 | B14: 7th Floor | C14: 1359.04 | D14: -56.77 | E14: -25.27 | F14: -169.84 | G14: 1.09 | H14: 15.47 | I14: 14.45 | J14: 92.59 | K14: 0 | L14: 0 | M14: 30.1 | N14: 0.42 | O14: =221.33*0 -> 0 | P14: =SUM(C14:O14) -> 1261.28 | Q14: 1 | R14: =Q14*P14 -> 1261.28 | S14: =R14*10.764 -> 13576.418 | U14: =R15/804 -> 1.5462687 | V14: =+S14-J14*10.764 -> 12579.779
A15: 10 | B15: 8th Floor | C15: 1397.11 | D15: -56.77 | E15: -26.46 | F15: -213.67 | G15: 1.09 | H15: 22.17 | I15: 21.02 | J15: 95.99 | K15: 0 | L15: 0 | M15: 0 | N15: 2.72 | O15: 0 | P15: =SUM(C15:O15) -> 1243.2 | Q15: 1 | R15: =Q15*P15 -> 1243.2 | S15: =R15*10.764 -> 13381.805 | V15: =+S15-J15*10.764 -> 12348.568
A16: 11 | B16: 9th Floor | C16: =C15 -> 1397.11 | D16: =D15 -> -56.77 | E16: =E15 -> -26.46 | F16: =F15 -> -213.67 | G16: =G15 -> 1.09 | H16: =H15 -> 22.17 | I16: =I15 -> 21.02 | J16: =J15 -> 95.99 | ... O16: =O15 -> 0 | P16: =SUM(C16:O16) -> 1243.2 | Q16: 1 | R16: =Q16*P16 -> 1243.2 | S16: =R16*10.764 -> 13381.805 | V16: =+S16-J16*10.764 -> 12348.568
A17: 12 | B17: 10th Floor | C17: =C16 -> 1397.11 | D17: =D16 -> -56.77 | E17: =E16 -> -26.46 | F17: =F16 -> -213.67 | G17: =G16 -> 1.09 | H17: =H16 -> 22.17 | I17: =I16 -> 21.02 | J17: =J16 -> 95.99 | ... N17: =N16 -> 2.72 | O17: 0 | P17: =SUM(C17:O17) -> 1243.2 | Q17: 1 | R17: =Q17*P17 -> 1243.2 | S17: =R17*10.764 -> 13381.805 | V17: =+S17-J17*10.764 -> 12348.568
A18: 13 | B18: 11th Floor | C18: =C17 -> 1397.11 | D18: =D17 -> -56.77 | E18: =E17 -> -26.46 | F18: =F17 -> -213.67 | G18: =G17 -> 1.09 | H18: =H17 -> 22.17 | I18: =I17 -> 21.02 | J18: =J17 -> 95.99 | ... N18: =N17 -> 2.72 | O18: 0 | P18: =SUM(C18:O18) -> 1243.2 | Q18: 1 | R18: =Q18*P18 -> 1243.2 | S18: =R18*10.764 -> 13381.805 | V18: =+S18-J18*10.764 -> 12348.568 | AA18: =1630*9 -> 14670
A19: 14 | B19: 12th Floor | C19: =C18 -> 1397.11 | D19: =D18 -> -56.77 | E19: =E18 -> -26.46 | F19: =F18 -> -213.67 | G19: =G18 -> 1.09 | H19: =H18 -> 22.17 | I19: =I18 -> 21.02 | J19: =J18 -> 95.99 | ... N19: =N18 -> 2.72 | O19: 0 | P19: =SUM(C19:O19) -> 1243.2 | Q19: 1 | R19: =Q19*P19 -> 1243.2 | S19: =R19*10.764 -> 13381.805 | V19: =+S19-J19*10.764 -> 12348.568 | AA19: =+AA18*10.764 -> 157907.88
A20: 15 | B20: 13th Floor | C20: =C19 -> 1397.11 | D20: =D19 -> -56.77 | E20: =E19 -> -26.46 | F20: =F19 -> -213.67 | G20: =G19 -> 1.09 | H20: =H19 -> 22.17 | I20: =I19 -> 21.02 | J20: =J19 -> 95.99 | ... N20: =N19 -> 2.72 | O20: 0 | P20: =SUM(C20:O20) -> 1243.2 | Q20: 1 | R20: =Q20*P20 -> 1243.2 | S20: =R20*10.764 -> 13381.805 | V20: =+S20-J20*10.764 -> 12348.568 | AA20: =+AA19*1300 -> 205280244
A21: 16 | B21: 14th Floor | C21: 1410.34 | D21: -56.77 | E21: -26.46 | F21: -188.51 | G21: 1.09 | H21: 15.47 | I21: 14.5 | J21: 96.21 | K21: 0 | L21: 0 | M21: 0 | N21: 0.42 | O21: =224.19*0 -> 0 | P21: =SUM(C21:O21) -> 1266.29 | Q21: 1 | R21: =Q21*P21 -> 1266.29 | S21: =R21*10.764 -> 13630.346 | V21: =+S21-J21*10.764 -> 12594.741 | AA21: =+AA20/10^7 -> 20.528024
A22: 17 | B22: 15th Floor | C22: =C20 -> 1397.11 | D22: =D20 -> -56.77 | E22: =E20 -> -26.46 | F22: =F20 -> -213.67 | G22: =G20 -> 1.09 | H22: =H20 -> 22.17 | I22: =I20 -> 21.02 | J22: =J20 -> 95.99 | ... O22: =O20 -> 0 | P22: =SUM(C22:O22) -> 1243.2 | Q22: 1 | R22: =Q22*P22 -> 1243.2 | S22: =R22*10.764 -> 13381.805 | T22: =R22*3 -> 3729.6 | V22: =+S22-J22*10.764 -> 12348.568
A23: 18 | B23: 16th Floor | C23: =C22 -> 1397.11 | D23: =D22 -> -56.77 | E23: =E22 -> -26.46 | F23: =F22 -> -213.67 | G23: =G22 -> 1.09 | H23: =H22 -> 22.17 | I23: =I22 -> 21.02 | J23: =J22 -> 95.99 | ... O23: =O22 -> 0 | P23: =SUM(C23:O23) -> 1243.2 | Q23: 1 | R23: =Q23*P23 -> 1243.2 | S23: =R23*10.764 -> 13381.805 | V23: =+S23-J23*10.764 -> 12348.568
A24: 19 | B24: 17th Floor | C24: 1415.01 | D24: -56.77 | E24: -26.13 | F24: -170.18 | G24: 0 | H24: 30.94 | I24: 29 | J24: 94.98 | K24: 0 | L24: 0 | M24: 0 | N24: =N23 -> 2.72 | O24: 0 | P24: =SUM(C24:O24) -> 1319.57 | Q24: 1 | R24: =Q24*P24 -> 1319.57 | S24: =R24*10.764 -> 14203.851 | V24: =+S24-J24*10.764 -> 13181.487
A25: 20 | B25: 18th Floor | C25: =C24 -> 1415.01 | D25: =D24 -> -56.77 | E25: =E24 -> -26.13 | F25: =F24 -> -170.18 | G25: =G24 -> 0 | H25: =H24 -> 30.94 | I25: =I24 -> 29 | J25: =J24 -> 94.98 | ... O25: =O24 -> 0 | P25: =SUM(C25:O25) -> 1319.57 | Q25: 1 | R25: =Q25*P25 -> 1319.57 | S25: =R25*10.764 -> 14203.851 | V25: =+S25-J25*10.764 -> 13181.487
A26: 21 | B26: 19th Floor | C26: =C25 -> 1415.01 | D26: =D25 -> -56.77 | E26: =E25 -> -26.13 | F26: =F25 -> -170.18 | G26: =G25 -> 0 | H26: =H25 -> 30.94 | I26: =I25 -> 29 | J26: =J25 -> 94.98 | ... O26: =O25 -> 0 | P26: =SUM(C26:O26) -> 1319.57 | Q26: 1 | R26: =Q26*P26 -> 1319.57 | S26: =R26*10.764 -> 14203.851 | V26: =+S26-J26*10.764 -> 13181.487
A27: 22 | B27: 20th Floor | C27: =C26 -> 1415.01 | D27: =D26 -> -56.77 | E27: =E26 -> -26.13 | F27: =F26 -> -170.18 | G27: =G26 -> 0 | H27: =H26 -> 30.94 | I27: =I26 -> 29 | J27: =J26 -> 94.98 | ... O27: =O26 -> 0 | P27: =SUM(C27:O27) -> 1319.57 | Q27: 1 | R27: =Q27*P27 -> 1319.57 | S27: =R27*10.764 -> 14203.851 | V27: =+S27-J27*10.764 -> 13181.487
A28: 23 | B28: 21st Floor | C28: 1434.59 | D28: -56.77 | E28: -26.13 | F28: -145.98 | G28: 0 | H28: 24.22 | I28: 22.47 | J28: 88.39 | K28: 0 | L28: 0 | M28: 0 | N28: 0.42 | O28: =237.82*0 -> 0 | P28: =SUM(C28:O28) -> 1341.21 | Q28: 1 | R28: =Q28*P28 -> 1341.21 | S28: =R28*10.764 -> 14436.784 | V28: =+S28-J28*10.764 -> 13485.354
A29: 24 | B29: 22nd Floor | C29: =C24 -> 1415.01 | D29: =D24 -> -56.77 | E29: =E24 -> -26.13 | F29: =F24 -> -170.18 | G29: =G24 -> 0 | H29: =H24 -> 30.94 | I29: =I24 -> 29 | J29: =J24 -> 94.98 | ... O29: =O24 -> 0 | P29: =SUM(C29:O29) -> 1319.57 | Q29: 1 | R29: =Q29*P29 -> 1319.57 | S29: =R29*10.764 -> 14203.851 | V29: =+S29-J29*10.764 -> 13181.487
A30: 25 | B30: 23rd Floor | C30: =C25 -> 1415.01 | D30: -56.77 | E30: -26.13 | F30: -171.14 | G30: 0 | H30: 39.34 | I30: 28.95 | J30: 90.37 | K30: =K25 -> 0 | L30: =L25 -> 0 | M30: =M25 -> 0 | N30: 2.72 | O30: =O25 -> 0 | P30: =SUM(C30:O30) -> 1322.35 | Q30: 1 | R30: =Q30*P30 -> 1322.35 | S30: =R30*10.764 -> 14233.775 | U30: 38442 | V30: =+S30-J30*10.764 -> 13261.033
A31: 26 | B31: 24th Floor | C31: =C30 -> 1415.01 | D31: =D30 -> -56.77 | E31: =E30 -> -26.13 | F31: =F30 -> -171.14 | G31: =G30 -> 0 | H31: =H30 -> 39.34 | I31: =I30 -> 28.95 | J31: =J30 -> 90.37 | ... O31: =O30 -> 0 | P31: =SUM(C31:O31) -> 1322.35 | Q31: 1 | R31: =Q31*P31 -> 1322.35 | S31: =R31*10.764 -> 14233.775 | U31: =U30*3.5 -> 134547 | V31: =+S31-J31*10.764 -> 13261.033
A32: 27 | B32: 25th Floor | C32: =C31 -> 1415.01 | D32: =D31 -> -56.77 | E32: =E31 -> -26.13 | F32: =F31 -> -171.14 | G32: =G31 -> 0 | H32: =H31 -> 39.34 | I32: =I31 -> 28.95 | J32: =J31 -> 90.37 | ... O32: =O31 -> 0 | P32: =SUM(C32:O32) -> 1322.35 | Q32: 1 | R32: =Q32*P32 -> 1322.35 | S32: =R32*10.764 -> 14233.775 | U32: =U31*725 -> 97546575 | V32: =+S32-J32*10.764 -> 13261.033
A33: 28 | B33: 26th Floor | C33: =C32 -> 1415.01 | D33: =D32 -> -56.77 | E33: =E32 -> -26.13 | F33: =F32 -> -171.14 | G33: =G32 -> 0 | H33: =H32 -> 39.34 | I33: =I32 -> 28.95 | J33: =J32 -> 90.37 | ... O33: =O32 -> 0 | P33: =SUM(C33:O33) -> 1322.35 | Q33: 1 | R33: =Q33*P33 -> 1322.35 | S33: =R33*10.764 -> 14233.775 | V33: =+S33-J33*10.764 -> 13261.033
A34: 29 | B34: 27th Floor | C34: =C30 -> 1415.01 | D34: =D30 -> -56.77 | E34: =E30 -> -26.13 | F34: =F30 -> -171.14 | G34: =G30 -> 0 | H34: =H30 -> 39.34 | I34: =I30 -> 28.95 | J34: =J30 -> 90.37 | ... O34: =O30 -> 0 | P34: =SUM(C34:O34) -> 1322.35 | Q34: 1 | R34: =Q34*P34 -> 1322.35 | S34: =R34*10.764 -> 14233.775 | V34: =+S34-J34*10.764 -> 13261.033
A35: 30 | B35: 28th Floor | C35: 1434.59 | D35: -56.77 | E35: -26.13 | F35: -145.98 | G35: 0 | H35: 28.44 | I35: 22.47 | J35: 86.09 | K35: 0 | L35: 0 | M35: 0 | N35: 0.42 | O35: =234.42*0 -> 0 | P35: =SUM(C35:O35) -> 1343.13 | Q35: 1 | R35: =Q35*P35 -> 1343.13 | S35: =R35*10.764 -> 14457.451 | V35: =+S35-J35*10.764 -> 13530.779
A36: 31 | B36: 29th Floor | C36: =C30 -> 1415.01 | D36: =D30 -> -56.77 | E36: =E30 -> -26.13 | F36: =F30 -> -171.14 | G36: =G30 -> 0 | H36: =H30 -> 39.34 | I36: =I30 -> 28.95 | J36: =J30 -> 90.37 | ... O36: =O30 -> 0 | P36: =SUM(C36:O36) -> 1322.35 | Q36: 1 | R36: =Q36*P36 -> 1322.35 | S36: =R36*10.764 -> 14233.775 | V36: =+S36-J36*10.764 -> 13261.033
A37: 32 | B37: 30th Floor | C37: =C30 -> 1415.01 | D37: =D30 -> -56.77 | E37: =E30 -> -26.13 | F37: =F30 -> -171.14 | G37: =G30 -> 0 | H37: =H30 -> 39.34 | I37: =I30 -> 28.95 | J37: =J30 -> 90.37 | ... O37: =O30 -> 0 | P37: =SUM(C37:O37) -> 1322.35 | Q37: 1 | R37: =Q37*P37 -> 1322.35 | S37: =R37*10.764 -> 14233.775 | V37: =+S37-J37*10.764 -> 13261.033
A38: 33 | B38: 31st Floor | C38: =C30 -> 1415.01 | D38: =D30 -> -56.77 | E38: =E30 -> -26.13 | F38: =F30 -> -171.14 | G38: =G30 -> 0 | H38: =H30 -> 39.34 | I38: =I30 -> 28.95 | J38: =J30 -> 90.37 | ... O38: =O30 -> 0 | P38: =SUM(C38:O38) -> 1322.35 | Q38: 1 | R38: =Q38*P38 -> 1322.35 | S38: =R38*10.764 -> 14233.775 | V38: =+S38-J38*10.764 -> 13261.033
A39: 34 | B39: 32nd Floor | C39: =C30 -> 1415.01 | D39: =D30 -> -56.77 | E39: =E30 -> -26.13 | F39: =F30 -> -171.14 | G39: =G30 -> 0 | H39: =H30 -> 39.34 | I39: =I30 -> 28.95 | J39: =J30 -> 90.37 | ... O39: =O30 -> 0 | P39: =SUM(C39:O39) -> 1322.35 | Q39: 1 | R39: =Q39*P39 -> 1322.35 | S39: =R39*10.764 -> 14233.775 | V39: =+S39-J39*10.764 -> 13261.033
A40: 35 | B40: 33rd Floor | C40: =C30 -> 1415.01 | D40: =D30 -> -56.77 | E40: =E30 -> -26.13 | F40: =F30 -> -171.14 | G40: =G30 -> 0 | H40: =H30 -> 39.34 | I40: =I30 -> 28.95 | J40: =J30 -> 90.37 | ... O40: =O30 -> 0 | P40: =SUM(C40:O40) -> 1322.35 | Q40: 1 | R40: =Q40*P40 -> 1322.35 | S40: =R40*10.764 -> 14233.775 | V40: =+S40-J40*10.764 -> 13261.033
...

Sheet Summary
A2: Summary Cost Estimate for Project - AVS Mulund as per DBOT
A3: Sr.No | B3: Particulars | C3: As per DBOT
C4: Total Construction Area in Sq. ft | E4: ='Construction Area'!S45 -> 650726.75
C5: Rate in Rs Per Sq Ft of CA | D5: Budget in Rs. Cr. | E5: Cost Incurred till date in Rs. Cr. | F5: Cost to Complete in Rs. Cr.
A6: 1 | B6: Preliminaries | C6: =D6*10^7/$E$4 -> 18.931488 | D6: =Preliminary!F13/10^7 -> 1.2319225 | E6: 0 | F6: =+D6-E6 -> 1.2319225
A7: 2 | B7: Civil | C7: =D7*10^7/$E$4 -> 1580.8539 | D7: =(SUM('Cost Sheet Tower'!I5:I38)/10^7)+(SUM('Cost Sheet office'!I6:I11)/10^7) -> 102.87039 | E7: 0 | F7: =+D7-E7 -> 102.87039
A8: 3 | B8: Finishing | C8: =D8*10^7/$E$4 -> 500.2137 | D8: =((SUM('Cost Sheet Tower'!I39:I99))/10^7)+((SUM('Cost Sheet office'!I13:I48)/10^7)) -> 32.550243 | E8: 0 | F8: =+D8-E8 -> 32.550243
A9: 4 | B9: MEP | C9: =D9*10^7/$E$4 -> 368.26196 | D9: =(SUM('Cost Sheet Tower'!I100:I110))/10^7 -> 23.963791 | E9: 0 | F9: =+D9-E9 -> 23.963791
A10: 5 | B10: MEP NTA | C10: =D10*10^7/$E$4 -> 114.6627 | D10: =(SUM('Cost Sheet Tower'!I111:I117))/10^7 -> 7.4614088 | E10: 0 | F10: =+D10-E10 -> 7.4614088
A11: 6 | B11: MEP EXTERNAL | C11: =D11*10^7/$E$4 -> 31.525306 | D11: =(SUM('Cost Sheet Tower'!I118:I125))/10^7 -> 2.051436 | E11: 0 | F11: =+D11-E11 -> 2.051436
A12: 7 | B12: Amenities | C12: =D12*10^7/$E$4 -> 57.888061 | D12: =Amenities!F29/10^7 -> 3.766931 | E12: 0 | F12: =+D12-E12 -> 3.766931
A13: 8 | B13: External Development | C13: =D13*10^7/$E$4 -> 71.596849 | D13: ='Cost Sheet Tower'!I127/10^7 -> 4.6589985 | E13: 0 | F13: =+D13-E13 -> 4.6589985
A14: 9 | B14: Post Construction | C14: 15 | D14: =(C14*E4)/10^7 -> 0.97609012 | E14: 0 | F14: =+D14-E14 -> 0.97609012
B15: Total | C15: =D15*10^7/$E$4 -> 2758.9339 | D15: =SUBTOTAL(9,D6:D14) -> 179.53121 | E15: =SUBTOTAL(9,E7:E13) -> 0 | F15: =SUBTOTAL(9,F6:F14) -> 179.53121
A16: 9 | B16: Escalation @ 3% | C16: =D16*10^7/$E$4 -> 82.768018 | D16: =+D15*3% -> 5.3859363 | E16: =+E15*4% -> 0 | F16: =+D16-E16 -> 5.3859363
A17: 10 | B17: Contingency @ 4% | C17: =D17*10^7/$E$4 -> 110.35736 | D17: =+D15*4% -> 7.1812484 | E17: =+E15*5% -> 0 | F17: =+D17-E17 -> 7.1812484
B18: Total construction cost excluding Taxes | C18: =D18*10^7/$E$4 -> 2952.0593 | D18: =SUBTOTAL(9,D6:D17) -> 192.09839 | E18: =SUBTOTAL(9,E7:E17) -> 0 | F18: =SUBTOTAL(9,F6:F17) -> 192.09839
A19: 11 | B19: GST 18% | C19: =D19*10^7/$E$4 -> 531.37067 | D19: =+D18*0.18 -> 34.577711 | E19: =+E18*0.18 -> 0 | F19: =+F18*0.18 -> 34.577711
B20: Total construction cost with Taxes | C20: =D20*10^7/$E$4 -> 3483.43 | D20: =SUBTOTAL(9,D6:D19) -> 226.67611 | E20: =SUBTOTAL(9,E7:E19) -> 0 | F20: =SUBTOTAL(9,F6:F19) -> 226.67611
F21: 2268500000
A23: Summary Cost Estimate for Project - AVS Mulund as per DBOT (Flats)
A24: Sr.No | B24: Particulars | C24: As per DBOT
C25: Total Construction Area in Sq. ft | E25: ='Construction Area'!S45 -> 650726.75
C26: Rate in Rs Per Sq Ft of CA | D26: Budget in Rs. Cr. | E26: Cost Incurred till date in Rs. Cr. | F26: Cost to Complete in Rs. Cr.
A27: 1 | B27: Preliminaries | C27: =D27*10^7/$E$4 -> 18.931488 | D27: =D6 -> 1.2319225 | E27: 0 | F27: =+D27-E27 -> 1.2319225 | H27: =D27+D47 -> 1.2319225 | K27: =H27=D6 -> TRUE
A28: 2 | B28: Civil | C28: =D28*10^7/$E$4 -> 1578.6902 | D28: =(SUM('Cost Sheet Tower'!I5:I38))/10^7 -> 102.72959 | E28: 0 | F28: =+D28-E28 -> 102.72959 | H28: =D28+D48 -> 102.87039 | K28: =H28=D7 -> TRUE
A29: 3 | B29: Finishing | C29: =D29*10^7/$E$4 -> 437.67624 | D29: =((SUM('Cost Sheet Tower'!I39:I99))/10^7) -> 28.480764 | E29: 0 | F29: =+D29-E29 -> 28.480764 | H29: =D29+D49 -> 32.550243 | K29: =H29=D8 -> TRUE
A30: 4 | B30: MEP | C30: =D30*10^7/$E$4 -> 368.26196 | D30: =D9 -> 23.963791 | E30: 0 | F30: =+D30-E30 -> 23.963791 | H30: =D30+D50 -> 23.963791 | K30: =H30=D9 -> TRUE
A31: 5 | B31: MEP NTA | C31: =D31*10^7/$E$4 -> 114.6627 | D31: =D10 -> 7.4614088 | E31: 0 | F31: =+D31-E31 -> 7.4614088 | H31: =D31+D51 -> 7.4614088 | K31: =H31=D10 -> TRUE
A32: 6 | B32: MEP EXTERNAL | C32: =D32*10^7/$E$4 -> 31.525306 | D32: =D11 -> 2.051436 | E32: 0 | F32: =+D32-E32 -> 2.051436 | H32: =D32+D52 -> 2.051436 | K32: =H32=D11 -> TRUE
A33: 7 | B33: Amenities | C33: =D33*10^7/$E$4 -> 57.888061 | D33: =D12 -> 3.766931 | E33: 0 | F33: =+D33-E33 -> 3.766931 | H33: =D33+D53 -> 3.766931 | K33: =H33=D12 -> TRUE
A34: 8 | B34: External Development | C34: =D34*10^7/$E$4 -> 71.596849 | D34: =D13 -> 4.6589985 | E34: 0 | F34: =+D34-E34 -> 4.6589985 | H34: =D34+D54 -> 4.6589985 | K34: =H34=D13 -> TRUE
A35: 9 | B35: Post Construction | C35: 15 | D35: =D14 -> 0.97609012 | E35: 0 | F35: =+D35-E35 -> 0.97609012 | H35: =D35+D55 -> 0.97609012 | K35: =H35=D14 -> TRUE
B36: Total | C36: =D36*10^7/$E$4 -> 2694.2328 | D36: =SUBTOTAL(9,D27:D35) -> 175.32093 | E36: =SUBTOTAL(9,E28:E34) -> 0 | F36: =SUBTOTAL(9,F27:F35) -> 175.32093
A37: 9 | B37: Escalation @ 3% | C37: =D37*10^7/$E$4 -> 80.826983 | D37: =+D36*3% -> 5.259628 | E37: =+E36*4% -> 0 | F37: =+D37-E37 -> 5.259628
A38: 10 | B38: Contingency @ 4% | C38: =D38*10^7/$E$4 -> 107.76931 | D38: =+D36*4% -> 7.0128373 | E38: =+E36*5% -> 0 | F38: =+D38-E38 -> 7.0128373
B39: Total construction cost excluding Taxes | C39: =D39*10^7/$E$4 -> 2882.8291 | D39: =SUBTOTAL(9,D27:D38) -> 187.5934 | E39: =SUBTOTAL(9,E28:E38) -> 0 | F39: =SUBTOTAL(9,F27:F38) -> 187.5934
A40: 11 | B40: GST 18% | C40: =D40*10^7/$E$4 -> 518.90923 | D40: =+D39*0.18 -> 33.766812 | E40: =+E39*0.18 -> 0 | F40: =+F39*0.18 -> 33.766812
B41: Total construction cost with Taxes | C41: =D41*10^7/$E$4 -> 3401.7383 | D41: =SUBTOTAL(9,D27:D40) -> 221.36021 | E41: =SUBTOTAL(9,E28:E40) -> 0 | F41: =SUBTOTAL(9,F27:F40) -> 221.36021
A43: Summary Cost Estimate for Project - AVS Mulund as per DBOT (Office)
...

Sheet Cost Sheet Tower
A2: Detailed Cost Estimate
E3: CA | G3: ='Construction Area'!S45 -> 650726.75 | H3: Sft
A4: Sr. No | B4: Description | C4: Rate Psf of Const Area | D4: % Completed | E4: Balance % | F4: Unit | G4: Quantity | H4: Rate | I4: Total Cost | J4: Cost till date | K4: Balance Cost | L4: Consumption
A5: SHELL AND CORE | B5: Excavation | C5: =I5/$G$3 -> 16.074129 | D5: 0 | E5: =+(1-D5) -> 1 | F5: Cu M | G5: =Excavation!I12 -> 22223.204 | H5: =I5/G5 -> 470.67314 | I5: =Excavation!K12 -> 10459865 | J5: =+I5*D5 -> 0 | K5: =+E5*I5 -> 10459865
B6: Shore Piling | C6: =I6/$G$3 -> 19.728638 | D6: 0 | E6: =+(1-D6) -> 1 | F6: Nos. | G6: ='Shore Pile'!M3 -> 200 | H6: =I6/G6 -> 64189.763 | I6: ='Shore Pile'!F12 -> 12837953 | J6: =+I6*D6 -> 0 | K6: =+E6*I6 -> 12837953
B7: Backfiling | C7: =I7/$G$3 -> 11.464612 | D7: 0 | E7: =+(1-D7) -> 1 | F7: Cu M | G7: =Excavation!I13 -> 6666.9613 | H7: ='Rate List - Flats'!G277 -> 1119 | I7: =G7*H7 -> 7460329.8 | J7: =+I7*D7 -> 0 | K7: =+E7*I7 -> 7460329.8
B8: Antitermite | C8: =I8/$G$3 -> 0.30006537 | D8: 0 | E8: =+(1-D8) -> 1 | F8: Sq M | G8: =Excavation!I14 -> 2077.24 | H8: ='Rate List - Flats'!G279 -> 94 | I8: =G8*H8 -> 195260.56 | J8: =+I8*D8 -> 0 | K8: =+E8*I8 -> 195260.56
B9: Soiling | C9: =I9/$G$3 -> 0 | D9: 0 | E9: =+(1-D9) -> 1 | F9: Sq M | G9: 0 | I9: =G9*H9 -> 0 | J9: =+I9*D9 -> 0 | K9: =+E9*I9 -> 0
B10: Steel | C10: =I10/$G$3 -> 492.63644 | D10: 0 | E10: =+(1-D10) -> 1 | F10: Ton | G10: ='Concrete & Steel Summary'!I60 -> 4042.0087 | H10: ='Rate List - Flats'!G245 -> 79310 | I10: =G10*H10 -> 3.2057171e+08 | J10: =+I10*D10 -> 0 | K10: =+E10*I10 -> 3.2057171e+08 | L10: =G10*1000/G3 -> 6.2115299 | M10: Kg/sft
B11: Concrete | C11: =I11/$G$3 -> 510.78891 | D11: 0 | E11: =+(1-D11) -> 1 | F11: Cu M | G11: ='Concrete & Steel Summary'!D80 -> 32058.57 | H11: =I11/G11 -> 10368.023 | I11: ='Concrete & Steel Summary'!F80 -> 3.32384e+08 | J11: =+I11*D11 -> 0 | K11: =+E11*I11 -> 3.32384e+08 | L11: =G11/G3 -> 0.049265794
B12: Mivan Shuttering | C12: =I12/$G$3 -> 137.87359 | D12: 0 | E12: =+(1-D12) -> 1 | F12: Sq M | G12: ='Shuttering Summary'!C4 -> 119624.04 | H12: ='Rate List - Flats'!G247 -> 750 | I12: =G12*H12 -> 89718033 | J12: =+I12*D12 -> 0 | K12: =+E12*I12 -> 89718033 | L12: =G12/G3 -> 0.18383145
B13: Conventional Shuttering | C13: =I13/$G$3 -> 85.63184 | D13: 0 | E13: =+(1-D13) -> 1 | F13: Sq M | G13: ='Shuttering Summary'!C3 -> 51310.247 | H13: ='Rate List - Flats'!G246 -> 1086 | I13: =G13*H13 -> 55722929 | J13: =+I13*D13 -> 0 | K13: =+E13*I13 -> 55722929 | L13: =G13/G3 -> 0.078850681
B14: Block Work | C14: =I14/$G$3 -> 58.051446 | D14: 0 | E14: =+(1-D14) -> 1 | F14: Sq M | G14: ='Blockwork & Plaster & Painting'!G3 -> 13162.24 | H14: ='Rate List - Flats'!G264 -> 2870 | I14: =G14*H14 -> 37775629 | J14: =+I14*D14 -> 0 | K14: =+E14*I14 -> 37775629
B15: Plum Concrete | C15: =I15/$G$3 -> 61.723479 | D15: 0 | E15: =+(1-D15) -> 1 | F15: Cu M | G15: ='Measurement Sheet'!F363 -> 6132.0792 | H15: ='Rate List - Flats'!G237 -> 6550 | I15: =G15*H15 -> 40165119 | J15: =+I15*D15 -> 0 | K15: =+E15*I15 -> 40165119
B16: Plaster | L16: =+SUM(I10:I13)/G3 -> 1226.9308
B17: Internal Cement Plaster (Wall Area) | C17: =I17/$G$3 -> 4.5845157 | D17: 0 | E17: =+(1-D17) -> 1 | F17: Sq M | G17: =VLOOKUP(B17,'Internal Finishes Flats'!$B$1998:$F$2038,3,FALSE) -> 5229.288 | H17: =VLOOKUP(B17,'Internal Finishes Flats'!$B$1998:$F$2038,4,FALSE) -> 570.492 | I17: =G17*H17 -> 2983267 | J17: =+I17*D17 -> 0 | K17: =+E17*I17 -> 2983267
B18: Internal Cement Plaster (Ceiling Area) | C18: =I18/$G$3 -> 0 | D18: 0 | E18: =+(1-D18) -> 1 | F18: Sq M | G18: =VLOOKUP(B18,'Internal Finishes Flats'!$B$1998:$F$2038,3,FALSE) -> 0 | H18: =VLOOKUP(B18,'Internal Finishes Flats'!$B$1998:$F$2038,4,FALSE) -> 0 | I18: =G18*H18 -> 0 | J18: =+I18*D18 -> 0 | K18: =+E18*I18 -> 0
B19: Internal Plastering - Back Coat | C19: =I19/$G$3 -> 20.895497 | D19: 0 | E19: =+(1-D19) -> 1 | F19: Sq M | G19: =VLOOKUP(B19,'Internal Finishes Flats'!$B$1998:$F$2038,3,FALSE) -> 23086.989 | H19: =VLOOKUP(B19,'Internal Finishes Flats'!$B$1998:$F$2038,4,FALSE) -> 588.95764 | I19: =G19*H19 -> 13597259 | J19: =+I19*D19 -> 0 | K19: =+E19*I19 -> 13597259
B20: External Plaster
B21: External Plastering - 15mm thick | C21: =I21/$G$3 -> 10.14004 | D21: 0 | E21: =+(1-D21) -> 1 | F21: Sq M | G21: =VLOOKUP(B21,'Internal Finishes Flats'!$B$1998:$F$2038,3,FALSE) -> 7211.834 | H21: =VLOOKUP(B21,'Internal Finishes Flats'!$B$1998:$F$2038,4,FALSE) -> 914.94 | I21: =G21*H21 -> 6598395.4 | J21: =+I21*D21 -> 0 | K21: =+E21*I21 -> 6598395.4
B22: Duct Plaster | C22: =I22/$G$3 -> 4.5488326 | D22: 0 | E22: =+(1-D22) -> 1 | F22: Sq M | G22: ='Blockwork & Plaster & Painting'!F11 -> 3846.085 | H22: ='Rate List - Flats'!G249 -> 769.626 | I22: =G22*H22 -> 2960047 | J22: =+I22*D22 -> 0 | K22: =+E22*I22 -> 2960047
B23: Waterproofing | I23: =G23*H23 -> 0 | J23: =+I23*D23 -> 0 | K23: =+E23*I23 -> 0
B24: Basecoat | C24: =I24/$G$3 -> 38.430284 | D24: 0 | E24: =+(1-D24) -> 1 | F24: Sq M | G24: =VLOOKUP(B24,Waterproofing!$B$147:$F$154,3,FALSE) -> 18586.112 | H24: =VLOOKUP(B24,Waterproofing!$B$147:$F$154,4,FALSE) -> 1345.5 | I24: =G24*H24 -> 25007614 | J24: =+I24*D24 -> 0 | K24: =+E24*I24 -> 25007614
B25: Terrace Waterproofing | C25: =I25/$G$3 -> 4.6591333 | D25: 0 | E25: =+(1-D25) -> 1 | F25: Sq M | G25: =VLOOKUP(B25,Waterproofing!$B$147:$F$154,3,FALSE) -> 1083.32 | H25: =VLOOKUP(B25,Waterproofing!$B$147:$F$154,4,FALSE) -> 2798.64 | I25: =G25*H25 -> 3031822.7 | J25: =+I25*D25 -> 0 | K25: =+E25*I25 -> 3031822.7
B26: Podium Waterproofing | C26: =I26/$G$3 -> 5.8399586 | D26: 0 | E26: =+(1-D26) -> 1 | F26: Sq M | G26: =VLOOKUP(B26,Waterproofing!$B$147:$F$154,3,FALSE) -> 1357.88 | H26: =VLOOKUP(B26,Waterproofing!$B$147:$F$154,4,FALSE) -> 2798.64 | I26: =G26*H26 -> 3800217.3 | J26: =+I26*D26 -> 0 | K26: =+E26*I26 -> 3800217.3
B27: Chajja Waterproofing | C27: =I27/$G$3 -> 5.6422041 | D27: 0 | E27: =+(1-D27) -> 1 | F27: Sq M | G27: =VLOOKUP(B27,Waterproofing!$B$147:$F$154,3,FALSE) -> 2728.75 | H27: =VLOOKUP(B27,Waterproofing!$B$147:$F$154,4,FALSE) -> 1345.5 | I27: =G27*H27 -> 3671533.1 | J27: =+I27*D27 -> 0 | K27: =+E27*I27 -> 3671533.1
B28: OHT Waterproofing | C28: =I28/$G$3 -> 1.5919809 | D28: 0 | E28: =+(1-D28) -> 1 | F28: Sq M | G28: =VLOOKUP(B28,Waterproofing!$B$147:$F$154,3,FALSE) -> 370.16 | H28: =VLOOKUP(B28,Waterproofing!$B$147:$F$154,4,FALSE) -> 2798.64 | I28: =G28*H28 -> 1035944.6 | J28: =+I28*D28 -> 0 | K28: =+E28*I28 -> 1035944.6
B29: Membrame Waterproofing | C29: =I29/$G$3 -> 7.2969175 | D29: 0 | E29: =+(1-D29) -> 1 | F29: Sq M | G29: =VLOOKUP(B29,Waterproofing!$B$147:$F$154,3,FALSE) -> 4128.956 | H29: =VLOOKUP(B29,Waterproofing!$B$147:$F$154,4,FALSE) -> 1150 | I29: =G29*H29 -> 4748299.4 | J29: =+I29*D29 -> 0 | K29: =+E29*I29 -> 4748299.4
B30: STP Waterproofing | C30: =I30/$G$3 -> 0.40805909 | D30: 0 | E30: =+(1-D30) -> 1 | F30: Sq M | G30: =VLOOKUP(B30,Waterproofing!$B$147:$F$154,3,FALSE) -> 94.88 | H30: =VLOOKUP(B30,Waterproofing!$B$147:$F$154,4,FALSE) -> 2798.64 | I30: =G30*H30 -> 265534.96 | J30: =+I30*D30 -> 0 | K30: =+E30*I30 -> 265534.96
B31: Brickbat | C31: =I31/$G$3 -> 17.783785 | D31: 0 | E31: =+(1-D31) -> 1 | F31: Cu M | G31: =VLOOKUP(B31,Waterproofing!$B$147:$F$154,3,FALSE) -> 1361.457 | H31: =VLOOKUP(B31,Waterproofing!$B$147:$F$154,4,FALSE) -> 8500 | I31: =G31*H31 -> 11572384 | J31: =+I31*D31 -> 0 | K31: =+E31*I31 -> 11572384
B32: Antiroot Waterproofing | C32: =I32/$G$3 -> 0.16360784 | D32: 0 | E32: =+(1-D32) -> 1 | F32: Cu M | G32: =VLOOKUP(B32,Waterproofing!$B$147:$F$155,3,FALSE) -> 133.08 | H32: =VLOOKUP(B32,Waterproofing!$B$147:$F$155,4,FALSE) -> 800 | I32: =G32*H32 -> 106464 | J32: =+I32*D32 -> 0 | K32: =+E32*I32 -> 106464
B33: Protection Board | C33: =I33/$G$3 -> 2.0494246 | D33: 0 | E33: =+(1-D33) -> 1 | F33: Cu M | G33: =VLOOKUP(B33,Waterproofing!$B$147:$F$156,3,FALSE) -> 2051.716 | H33: =VLOOKUP(B33,Waterproofing!$B$147:$F$156,4,FALSE) -> 650 | I33: =G33*H33 -> 1333615.4 | J33: =+I33*D33 -> 0 | K33: =+E33*I33 -> 1333615.4
B34: Int. Plaster Gypsum | I34: =G34*H34 -> 0 | J34: =+I34*D34 -> 0 | K34: =+E34*I34 -> 0
